Workbook

Sheet BATCH 1BTEST-1 8TH JUNE 25
A1: BAKLIWAL TUTORIALS
A2: JEE-2027 MAINS BTEST-01 RESULT 08TH JUNE 2025
A3: TOP 72 STUDENTS IN THE SUBJECT
A4: 73 - 144 STUDENTS IN THE SUBJECT
A5: 145 - 217 STUDENTS IN THE SUBJECT
B6: MEDIAN MARKS | D6: 40 | F6: 40 | H6: 54 | J6: 134
B7: MAX | D7: 100 | F7: 100 | H7: 100 | J7: 300
A8: TOTAL RANK | B8: STUDENT NAME | C8: ROLL NO. | D8: PHY | E8: PHY RANK | F8: CHEM | G8: CHE RANK | H8: MATHS | I8: MATH RANK | J8: TOTAL | K8: BRANCH
A9: 1 | B9: KETKI KULKARNI | C9: 27800409 | D9: 95 | E9: 3 | F9: 90 | G9: 2 | H9: 100 | I9: 1 | J9: 285 | K9: HO
A10: 2 | B10: KARTIK KULKARNI | C10: 27800404 | D10: 100 | E10: 1 | F10: 75 | G10: 12 | H10: 95 | I10: 3 | J10: 270 | K10: JS
A11: 3 | B11: JAYRAJ JUJAGAR | C11: 27800405 | D11: 90 | E11: 8 | F11: 80 | G11: 5 | H11: 100 | I11: 1 | J11: 270 | K11: JS
A12: 4 | B12: ANIMESH CHAVAN | C12: 27800403 | D12: 95 | E12: 3 | F12: 80 | G12: 5 | H12: 95 | I12: 3 | J12: 270 | K12: JS
A13: 5 | B13: YATHARTH APPASAHEB PATIL | C13: 27800014 | D13: 90 | E13: 8 | F13: 92 | G13: 1 | H13: 86 | I13: 18 | J13: 268 | K13: HO
A14: 6 | B14: SATVIKA MORE | C14: 27800410 | D14: 90 | E14: 8 | F14: 75 | G14: 12 | H14: 95 | I14: 3 | J14: 260 | K14: HO
A15: 7 | B15: AKHILESH GAIKWAD | C15: 27800407 | D15: 96 | E15: 2 | F15: 73 | G15: 18 | H15: 90 | I15: 11 | J15: 259 | K15: JS
A16: 8 | B16: AISHWARJA BEHERA | C16: 27800050 | D16: 90 | E16: 8 | F16: 72 | G16: 21 | H16: 95 | I16: 3 | J16: 257 | K16: HO
A17: 9 | B17: RAJDEEP KHANDU GAIKWAD | C17: 27800056 | D17: 91 | E17: 6 | F17: 76 | G17: 9 | H17: 90 | I17: 11 | J17: 257 | K17: JS
A18: 10 | B18: SANKET SHIVAPUTRA BUKKANURE | C18: 27800015 | D18: 95 | E18: 3 | F18: 71 | G18: 24 | H18: 90 | I18: 11 | J18: 256 | K18: HO
A19: 11 | B19: PIYUSH PAWAR | C19: 27800406 | D19: 90 | E19: 8 | F19: 75 | G19: 12 | H19: 90 | I19: 11 | J19: 255 | K19: JS
A20: 12 | B20: OJAS HUMNABADKAR | C20: 27800408 | D20: 91 | E20: 6 | F20: 73 | G20: 18 | H20: 90 | I20: 11 | J20: 254 | K20: JS
... A225: 217 | B225: ATHARV AJAYKUMAR PATIL | C225: 27800174 | D225: 0 | E225: 215 | F225: 5 | G225: 209 | H225: -10 | I225: 217 | J225: -5 | K225: HO

Sheet GRAND TEST-5 27.09.26
A1: BAKLIWAL TUTORIALS
A2: JEE-2027 GRAND TEST - 5 RESULT 1ST OCT 2026
A3: TOP 90 STUDENTS IN THE SUBJECT
A4: 91 - 180 STUDENTS IN THE SUBJECT
A5: 181 - 271 STUDENTS IN THE SUBJECT
B6: MEDIAN MARKS | D6: 22 | F6: 18 | H6: 26 | J6: 61
B7: MAX | D7: 100 | F7: 100 | H7: 100 | J7: 300
A8: TOTAL RANK | B8: STUDENT NAME | C8: ROLL NO. | D8: PHY | E8: PHY RANK | F8: CHEM | G8: CHE RANK | H8: MATHS | I8: MATH RANK | J8: TOTAL | K8: BRANCH | L8: BATCH | M8: SET | N8: MOB 1 | O8: MOB 2
A9: 1 | B9: DHANUSH HARSHVARDHAN SALAGALA | C9: 27379642 | D9: 90 | E9: 2 | F9: 87 | G9: 1 | H9: 82 | I9: 10 | J9: 259 | K9: JS | L9: WIZ | M9: B | N9: 7981415407 | O9: 9390146881
A10: 2 | B10: SUMIT ANNASAHEB TAKADE | C10: 27371780 | D10: 88 | E10: 3 | F10: 71 | G10: 3 | H10: 88 | I10: 5 | J10: 247 | K10: JS | L10: WOW | M10: C | N10: 8180875849 | O10: 9022866298
A11: 3 | B11: ARJUN RANJEET PATIL | C11: 27340819 | D11: 91 | E11: 1 | F11: 60 | G11: 14 | H11: 90 | I11: 4 | J11: 241 | K11: JS | L11: WOW | M11: B | N11: 9921866821 | O11: 9172352777
A12: 4 | B12: ARYAN SHAMKUMAR DESHMUKH | C12: 27343303 | D12: 81 | E12: 6 | F12: 70 | G12: 5 | H12: 85 | I12: 8 | J12: 236 | K12: JS | L12: WOW | M12: A | N12: 98221 77990 | O12: 9011183681
A13: 5 | B13: KARTIK KULKARNI | C13: 23000009 | D13: 85 | E13: 4 | F13: 56 | G13: 21 | H13: 91 | I13: 3 | J13: 232 | K13: JS | L13: WOW | M13: B | N13: 8767988859 | O13: 9767107237
A14: 6 | B14: JAYRAJ HUGAR | C14: 23000008 | D14: 77 | E14: 7 | F14: 60 | G14: 14 | H14: 87 | I14: 7 | J14: 224 | K14: JS | L14: WOW | M14: A | N14: 7972484107 | O14: 9423578791
A15: 7 | B15: KETKI KULKARNI | C15: 23000010 | D15: 68 | E15: 10 | F15: 55 | G15: 23 | H15: 100 | I15: 1 | J15: 223 | K15: JS | L15: WOW | M15: A | N15: 7720089049 | O15: 9881133121
A16: 7 | B16: PRAGUN VINEET RATHI | C16: 27343975 | D16: 70 | E16: 9 | F16: 65 | G16: 10 | H16: 88 | I16: 5 | J16: 223 | K16: JS | L16: WOW | M16: B | N16: 9372329320 | O16: 8610101414
A17: 9 | B17: AVADHOOT KULKARNI | C17: 27361589 | D17: 76 | E17: 8 | F17: 66 | G17: 9 | H17: 58 | I17: 29 | J17: 200 | K17: JS | L17: WOW | M17: B | N17: 9665990085 | O17: 9665990084
A18: 9 | B18: OJAS HUMNABADKAR | C18: 25800325 | D18: 68 | E18: 10 | F18: 63 | G18: 12 | H18: 69 | I18: 17 | J18: 200 | K18: JS | L18: WOW | M18: C | N18: 8275302471 | O18: 9421040072
A19: 11 | B19: VEDIKA REVANSIDDHA ANDHALKAR | C19: 27380101 | D19: 65 | E19: 15 | F19: 67 | G19: 8 | H19: 62 | I19: 20 | J19: 194 | K19: JS | L19: WOW | M19: C | N19: 9404677299 | O19: 9420692224
A20: 12 | B20: ARNAV THITE | C20: 26850027 | D20: 67 | E20: 13 | F20: 30 | G20: 80 | H20: 92 | I20: 2 | J20: 189 | K20: JS | L20: WOW | M20: C | N20: 9834722727 | O20: 8669170500
A21: 13 | B21: ANIMESH CHAVAN | C21: 23000004 | D21: 65 | E21: 15 | F21: 60 | G21: 14 | H21: 60 | I21: 25 | J21: 185 | K21: JS | L21: WOW | M21: A | N21: 9960630599 | O21: 9890308694
A22: 14 | B22: VEDASHRI NAGNATH MUNGAPATIL | C22: 27377476 | D22: 62 | E22: 21 | F22: 59 | G22: 18 | H22: 62 | I22: 20 | J22: 183 | K22: AC | M22: C | N22: 8530268747 | O22: 8080663711
A23: 15 | B23: ISHAN PHADE | C23: 27353204 | D23: 82 | E23: 5 | F23: 46 | G23: 35 | H23: 54 | I23: 37 | J23: 182 | K23: PANDHARPUR | M23: A | N23: 9890294146 | O23: 7218311148
A24: 16 | B24: SANKET SHIVAPUTRA BUKKANURE | C24: 27333715 | D24: 46 | E24: 43 | F24: 47 | G24: 33 | H24: 85 | I24: 8 | J24: 178 | K24: JS | L24: WOW | M24: B | N24: 9834215464 | O24: 9637259049
A25: 17 | B25: SRUSHTI RAJENDRA GHADAGE | C25: 27362786 | D25: 54 | E25: 31 | F25: 46 | G25: 35 | H25: 74 | I25: 12 | J25: 174 | K25: JS | L25: WOW | M25: B | N25: 9823959523 | O25: 7420898716
A26: 18 | B26: ARYAN SADIGALE | C26: 27355192 | D26: 44 | E26: 49 | F26: 70 | G26: 5 | H26: 57 | I26: 33 | J26: 171 | K26: PANDHARPUR | M26: A | N26: 9860701813 | O26: 9529277765
A27: 19 | B27: VAISHNAVI ALAND | C27: 27347172 | D27: 54 | E27: 31 | F27: 55 | G27: 23 | H27: 61 | I27: 22 | J27: 170 | K27: JS | L27: WOW | M27: A | N27: 6355368321 | O27: 9920379802
A28: 19 | B28: ARUSH AJIT KULKARNI | C28: 27109976 | D28: 54 | E28: 31 | F28: 38 | G28: 53 | H28: 78 | I28: 11 | J28: 170 | K28: JS | L28: WOW | M28: B | N28: 9922585585 | O28: 8485056658
A29: 19 | B29: RAJDEEP KHANDU GAIKWAD | C29: 27343132 | D29: 54 | E29: 31 | F29: 58 | G29: 19 | H29: 58 | I29: 29 | J29: 170 | K29: JS | L29: WOW | M29: B | N29: 8208396376 | O29: 9730945295
A30: 22 | B30: AISHWARJA BEHERA | C30: 27356474 | D30: 64 | E30: 18 | F30: 62 | G30: 13 | H30: 42 | I30: 73 | J30: 168 | K30: JS | L30: WOW | M30: C | N30: 9437497973 | O30: 8249643517
A31: 22 | B31: SHREYA ANIL ANKOLIKAR | C31: 27358598 | D31: 65 | E31: 15 | F31: 40 | G31: 49 | H31: 63 | I31: 18 | J31: 168 | K31: JS | L31: WIZ | M31: C | N31: 8698529100 | O31: 7020491283
A32: 24 | B32: SAYALI MADALE | C32: 23000024 | D32: 63 | E32: 19 | F32: 52 | G32: 28 | H32: 50 | I32: 49 | J32: 165 | K32: JS | L32: WOW | M32: C | N32: 9175343925 | O32: 8855832225
A33: 25 | B33: AKHILESH GAIKWAD | C33: 25800203 | D33: 56 | E33: 26 | F33: 38 | G33: 53 | H33: 70 | I33: 14 | J33: 164 | K33: JS | L33: WOW | M33: B | N33: 8605766966 | O33: 9422457543
A34: 26 | B34: SHREYA VIJAYKUMAR BIRADAR | C34: 27340955 | D34: 46 | E34: 43 | F34: 54 | G34: 25 | H34: 61 | I34: 22 | J34: 161 | K34: JS | L34: WOW | M34: A | N34: 9422941800 | O34: 8668220797
A35: 27 | B35: SATVIKA MORE | C35: 23000017 | D35: 45 | E35: 46 | F35: 54 | G35: 25 | H35: 60 | I35: 25 | J35: 159 | K35: JS | L35: WOW | M35: C | N35: 8766449082 | O35: 9028998317
A36: 28 | B36: TRISHA SHANKAR BHANDARI | C36: 27350345 | D36: 55 | E36: 28 | F36: 47 | G36: 33 | H36: 56 | I36: 36 | J36: 158 | K36: JS | L36: WOW | M36: C | N36: 9028286401 | O36: 9545896172
A37: 29 | B37: SHAURYA BORGAVKAR | C37: 27374439 | D37: 59 | E37: 24 | F37: 71 | G37: 3 | H37: 27 | I37: 126 | J37: 157 | K37: PANDHARPUR | M37: A | N37: 9823411119 | O37: 8551938181
A38: 30 | B38: SHRIYASH JADHAV | C38: 27358636 | D38: 39 | E38: 65 | F38: 69 | G38: 7 | H38: 48 | I38: 53 | J38: 156 | K38: PANDHARPUR | M38: A | N38: 9284108763 | O38: 7666762833
A39: 31 | B39: SAMRUDDHI RAJENDRAKUMAR KOLEKAR | C39: 27368316 | D39: 62 | E39: 21 | F39: 46 | G39: 35 | H39: 45 | I39: 61 | J39: 153 | K39: JS | L39: WIZ | M39: A | N39: 9373214938 | O39: 9028564509
A40: 31 | B40: SRUSHTI DINESH DHOTRE | C40: 27391023 | D40: 66 | E40: 14 | F40: 33 | G40: 70 | H40: 54 | I40: 37 | J40: 153 | K40: JS | L40: WIZ | M40: C
...

Sheet BATCH 2,3BTEST-1 22ND JUNE 25
A1: BAKLIWAL TUTORIALS
A2: JEE-2027 MAINS BTEST-01 RESULT 22 JUNE 2025
A3: TOP 39 STUDENTS IN THE SUBJECT
A4: 40 - 78 STUDENTS IN THE SUBJECT
A5: 79 - 118 STUDENTS IN THE SUBJECT
B6: MEDIAN MARKS | D6: 48 | F6: 32 | H6: 41 | J6: 113
B7: MAX | D7: 100 | F7: 100 | H7: 100 | J7: 300
A8: TOTAL RANK | B8: STUDENT NAME | C8: ROLL NO. | D8: PHY | E8: PHY RANK | F8: CHEM | G8: CHE RANK | H8: MATHS | I8: MATH RANK | J8: TOTAL | K8: BRANCH
A9: 1 | B9: PRAGUN VINEET RATHI | C9: 27800167 | D9: 100 | E9: 1 | F9: 81 | G9: 1 | H9: 76 | I9: 11 | J9: 257 | K9: HO
A10: 2 | B10: SURYAANSH SHRINIWAS CHIPPA | C10: 27800218 | D10: 92 | E10: 3 | F10: 66 | G10: 8 | H10: 90 | I10: 2 | J10: 248 | K10: HO
A11: 3 | B11: ANANYA GOVING ANAGUNDE | C11: 27800052 | D11: 90 | E11: 6 | F11: 77 | G11: 2 | H11: 75 | I11: 12 | J11: 242 | K11: HO
A12: 4 | B12: TANISHKA SHRIKANT MELGEPATIL | C12: 27800177 | D12: 91 | E12: 4 | F12: 73 | G12: 3 | H12: 75 | I12: 12 | J12: 239 | K12: HO
A13: 5 | B13: SHAMIK SUBHASH GAIKWAD | C13: 27800287 | D13: 91 | E13: 4 | F13: 66 | G13: 8 | H13: 81 | I13: 6 | J13: 238 | K13: JS
A14: 6 | B14: ADITI SHAILESH BANDE | C14: 27800257 | D14: 95 | E14: 2 | F14: 68 | G14: 6 | H14: 73 | I14: 14 | J14: 236 | K14: JS
A15: 7 | B15: GIRISH VITHAL NARANGKAR | C15: 27800202 | D15: 80 | E15: 11 | F15: 70 | G15: 4 | H15: 80 | I15: 7 | J15: 230 | K15: HO
A16: 8 | B16: SHRIYASH JADHAV | C16: 27900029 | D16: 76 | E16: 14 | F16: 63 | G16: 10 | H16: 82 | I16: 4 | J16: 221 | K16: PANDHARPUR
A17: 9 | B17: OM PRASHANT CHIVADSHETTI | C17: 27800236 | D17: 86 | E17: 8 | F17: 55 | G17: 15 | H17: 80 | I17: 7 | J17: 221 | K17: JS
A18: 10 | B18: ANSHULA MAHESH KSHIRSAGAR | C18: 27800304 | D18: 62 | E18: 34 | F18: 67 | G18: 7 | H18: 86 | I18: 3 | J18: 215 | K18: AC
A19: 11 | B19: SHRYEA VIJAYKUMAR BIRADAR | C19: 27800199 | D19: 76 | E19: 14 | F19: 44 | G19: 33 | H19: 82 | I19: 4 | J19: 202 | K19: HO
A20: 12 | B20: RAJNANDINI PRAVIN KALKOTE | C20: 27800234 | D20: 57 | E20: 45 | F20: 53 | G20: 16 | H20: 91 | I20: 1 | J20: 201 | K20: HO
... A126: 118 | B126: UTKARSH SHRIKANT BUVA | C126: 27800227 | D126: 4 | E126: 112 | F126: -2 | G126: 116 | H126: 8 | I126: 114 | J126: 10 | K126: JS
A127: STUDENTS WHOSE NAMES ARE NOT IN RANK LIST,WERE ABSENT FOR THE TEST

Sheet BATCH 1BTEST-2 6TH JULY 25
A1: BAKLIWAL TUTORIALS
A2: JEE-2027 MAINS BTEST-02 RESULT 06TH JULY 2025
A3: TOP 65 STUDENTS IN THE SUBJECT
A4: 66 - 130 STUDENTS IN THE SUBJECT
A5: 131 - 195 STUDENTS IN THE SUBJECT
B6: MEDIAN MARKS | D6: 35 | F6: 56 | H6: 54 | J6: 140
B7: MAX | D7: 100 | F7: 100 | H7: 100 | J7: 300
A8: TOTAL RANK | B8: STUDENT NAME | C8: ROLL NO. | D8: PHY | E8: PHY RANK | F8: CHEM | G8: CHE RANK | H8: MATHS | I8: MATH RANK | J8: TOTAL | K8: BRANCH
A9: 1 | B9: KARTIK KULKARNI | C9: 27800404 | D9: 95 | E9: 1 | F9: 95 | G9: 2 | H9: 100 | I9: 1 | J9: 290 | K9: JS
A10: 2 | B10: SUMIT ANNASAHEB TAKADE | C10: 27800077 | D10: 95 | E10: 1 | F10: 90 | G10: 6 | H10: 100 | I10: 1 | J10: 285 | K10: JS
A11: 3 | B11: KETKI AJIT KULKARNI | C11: 27800409 | D11: 90 | E11: 6 | F11: 90 | G11: 6 | H11: 100 | I11: 1 | J11: 280 | K11: HO
A12: 4 | B12: OJAS HUMNABADKAR | C12: 27800408 | D12: 95 | E12: 1 | F12: 95 | G12: 2 | H12: 90 | I12: 12 | J12: 280 | K12: JS
A13: 5 | B13: JAYRAJ JUJAGAR | C13: 27800405 | D13: 91 | E13: 5 | F13: 90 | G13: 6 | H13: 95 | I13: 7 | J13: 276 | K13: JS
A14: 6 | B14: SATVIKA SACHIN MORE | C14: 27800410 | D14: 95 | E14: 1 | F14: 90 | G14: 6 | H14: 90 | I14: 12 | J14: 275 | K14: HO
A15: 7 | B15: AISHWARJA BEHERA | C15: 27800050 | D15: 85 | E15: 9 | F15: 90 | G15: 6 | H15: 100 | I15: 1 | J15: 275 | K15: HO
A16: 8 | B16: YATHARTH APPASAHEB PATIL | C16: 27800014 | D16: 77 | E16: 15 | F16: 100 | G16: 1 | H16: 91 | I16: 9 | J16: 268 | K16: HO
A17: 9 | B17: SANKET SHIVAPUTRA BUKKANURE | C17: 27800015 | D17: 85 | E17: 9 | F17: 80 | G17: 41 | H17: 100 | I17: 1 | J17: 265 | K17: HO
A18: 10 | B18: ANIMESH CHAVAN | C18: 27800403 | D18: 80 | E18: 12 | F18: 85 | G18: 17 | H18: 100 | I18: 1 | J18: 265 | K18: JS
A19: 11 | B19: HARSHVARDHAN CHOUDHARI | C19: 27800028 | D19: 86 | E19: 8 | F19: 77 | G19: 47 | H19: 95 | I19: 7 | J19: 258 | K19: JS
A20: 12 | B20: SAYALI MADALE | C20: 27800411 | D20: 87 | E20: 7 | F20: 83 | G20: 26 | H20: 84 | I20: 24 | J20: 254 | K20: HO
... A203: 195 | B203: SHRIDHAR VIJAYKUMAR DASI | C203: 27800136 | D203: 12 | E203: 179 | F203: -9 | G203: 195 | H203: -11 | I203: 195 | J203: -8 | K203: AC
A204: STUDENTS WHOSE NAMES ARE NOT IN RANK LIST,WERE ABSENT FOR THE TEST

Sheet BATCH 2,3BTEST-2 20TH JULY 25
A1: BAKLIWAL TUTORIALS
A2: JEE-2027 MAINS BTEST-02 RESULT 20 JULY 2025
A3: TOP 45 STUDENTS IN THE SUBJECT
A4: 46 - 90 STUDENTS IN THE SUBJECT
A5: 91 - 134 STUDENTS IN THE SUBJECT
B6: MEDIAN MARKS | D6: 25.5 | F6: 26.5 | H6: 29 | J6: 85.5
B7: MAX | D7: 100 | F7: 100 | H7: 100 | J7: 300
A8: TOTAL RANK | B8: STUDENT NAME | C8: ROLL NO. | D8: PHY | E8: PHY RANK | F8: CHEM | G8: CHE RANK | H8: MATHS | I8: MATH RANK | J8: TOTAL | K8: BRANCH
A9: 1 | B9: PRAGUN VINEET RATHI | C9: 27800167 | D9: 82 | E9: 1 | F9: 90 | G9: 1 | H9: 83 | I9: 2 | J9: 255 | K9: HO
A10: 2 | B10: VARAD SAGAR MALANI | C10: 27800314 | D10: 72 | E10: 5 | F10: 86 | G10: 3 | H10: 85 | I10: 1 | J10: 243 | K10: HO
A11: 3 | B11: SHREYA VIJAYKUMAR BIRADAR | C11: 27800199 | D11: 73 | E11: 4 | F11: 87 | G11: 2 | H11: 74 | I11: 3 | J11: 234 | K11: HO
A12: 4 | B12: SURYAANSH SHRINIWAS CHIPPA | C12: 27800218 | D12: 79 | E12: 2 | F12: 83 | G12: 4 | H12: 63 | I12: 11 | J12: 225 | K12: HO
A13: 5 | B13: ANANYA GOVING ANAGUNDE | C13: 27800052 | D13: 77 | E13: 3 | F13: 78 | G13: 6 | H13: 65 | I13: 8 | J13: 220 | K13: HO
A14: 6 | B14: SHREYA MAHADEV VASTARE | C14: 27800298 | D14: 68 | E14: 8 | F14: 79 | G14: 5 | H14: 65 | I14: 8 | J14: 212 | K14: HO
A15: 7 | B15: GIRISH VITHAL NARANGKAR | C15: 27800202 | D15: 61 | E15: 11 | F15: 75 | G15: 7 | H15: 62 | I15: 13 | J15: 198 | K15: HO
A16: 8 | B16: TANISHKA SHRIKANT MELGEPATIL | C16: 27800177 | D16: 51 | E16: 20 | F16: 72 | G16: 8 | H16: 67 | I16: 6 | J16: 190 | K16: HO
A17: 9 | B17: RAJNANDINI PRAVIN KALKOTE | C17: 27800234 | D17: 71 | E17: 7 | F17: 57 | G17: 17 | H17: 53 | I17: 22 | J17: 181 | K17: HO
A18: 10 | B18: ANSHULA MAHESH KSHIRSAGAR | C18: 27800304 | D18: 59 | E18: 12 | F18: 61 | G18: 12 | H18: 59 | I18: 16 | J18: 179 | K18: AC
A19: 11 | B19: SHRUTI SHIVAJI KANHERE | C19: 27800308 | D19: 64 | E19: 9 | F19: 50 | G19: 27 | H19: 63 | I19: 11 | J19: 177 | K19: JS
A20: 12 | B20: MRUNALI SATISH BARAD | C20: 27800248 | D20: 40 | E20: 35 | F20: 60 | G20: 14 | H20: 66 | I20: 7 | J20: 166 | K20: HO
... A71: 63 | B71: SAMRUDDHI SUNIL BIRAJDAR | C71: 27800205 | D71: 39 | E71: 37 | F71: 22 | G71: 76 | H71: 28 | I71: 69 | J71: 89 | K71: HO
A72: 64 | B72: RUTURAJ MANE | D72: 14 | E72: 96 | F72: 26 | G72: 68 | H72: 49 | I72: 29 | J72: 89 | K72: PANDHARPUR
A73: 65 | B73: ATHARVA GHONGADE | C73: 27900028 | D73: 28 | E73: 62 | F73: 30 | G73: 60 | H73: 30 | I73: 64 | J73: 88 | K73: PANDHARPUR
A74: 66 | B74: RAJWARDHAN GUND | C74: 27900033 | D74: 15 | E74: 92 | F74: 40 | G74: 44 | H74: 33 | I74: 57 | J74: 88 | K74: PANDHARPUR
A75: 67 | B75: VAINATEY KARCHE | C75: 27900038 | D75: 23 | E75: 75 | F75: 18 | G75: 86 | H75: 47 | I75: 31 | J75: 88 | K75: PANDHARPUR
A76: 68 | B76: SHLOK SANTOSH GHODAKE | C76: 27800265 | D76: 24 | E76: 71 | F76: 14 | G76: 99 | H76: 45 | I76: 34 | J76: 83 | K76: JS
A77: 69 | B77: PRUTHVIRAJ SHAMBHULING WALE | C77: 27800222 | D77: 24 | E77: 71 | F77: 32 | G77: 56 | H77: 25 | I77: 76 | J77: 81 | K77: JS
A78: 70 | B78: REVATI UMESH BHOJANE | C78: 27800321 | D78: 25 | E78: 68 | F78: 15 | G78: 96 | H78: 40 | I78: 40 | J78: 80 | K78: HO
A79: 71 | B79: DEVDATH RAMCHANDRA NALLA | C79: 27800306 | D79: 44 | E79: 27 | F79: 26 | G79: 68 | H79: 9 | I79: 118 | J79: 79 | K79: AC
A80: 72 | B80: ABHISHEK PARSHURAM KADACHE | C80: 27800263 | D80: 23 | E80: 75 | F80: 20 | G80: 80 | H80: 34 | I80: 53 | J80: 77 | K80: HO
A81: 73 | B81: MANASI MAHESH MANURE | C81: 27800316 | D81: 14 | E81: 96 | F81: 45 | G81: 32 | H81: 17 | I81: 99 | J81: 76 | K81: AC
A82: 74 | B82: HARSHAD RAMCHANDRA TIRTHANKAR | C82: 27800200 | D82: 12 | E82: 106 | F82: 41 | G82: 43 | H82: 22 | I82: 83 | J82: 75 | K82: JS
A83: 75 | B83: VINAYAK RAMKRISHNA SHRIGUPKAR | C83: 27800280 | D83: 31 | E83: 48 | F83: 19 | G83: 81 | H83: 25 | I83: 76 | J83: 75 | K83: JS
A84: 76 | B84: VEDIKA PURUSHOTTAM WADDEPALLI | C84: 27800285 | D84: 24 | E84: 71 | F84: 27 | G84: 66 | H84: 22 | I84: 83 | J84: 73 | K84: AC
... A142: 134 | B142: SAMARTH SHIVAYYA MATHPATI | C142: 27800240 | D142: 6 | E142: 117 | F142: -9 | G142: 134 | H142: -4 | I142: 134 | J142: -7 | K142: HO
A143: STUDENTS WHOSE NAMES ARE NOT IN RANK LIST,WERE ABSENT FOR THE TEST

Sheet BTEST-303 AUG 25
A1: BAKLIWAL TUTORIALS
A2: JEE-2027 MAINS BTEST-03 RESULT 03RD AUGUST 2025
A3: TOP 117 STUDENTS IN THE SUBJECT
A4: 118 - 234 STUDENTS IN THE SUBJECT
A5: 235 - 349 STUDENTS IN THE SUBJECT
B6: MEDIAN MARKS | D6: 24 | F6: 51 | H6: 36 | J6: 110
B7: MAX | D7: 100 | F7: 100 | H7: 100 | J7: 300
A8: TOTAL RANK | B8: STUDENT NAME | C8: ROLL NO. | D8: PHY | E8: PHY RANK | F8: CHEM | G8: CHE RANK | H8: MATHS | I8: MATH RANK | J8: TOTAL | K8: BRANCH
A9: 1 | B9: ANIMESH CHAVAN | C9: 27800403 | D9: 90 | E9: 3 | F9: 96 | G9: 1 | H9: 91 | I9: 1 | J9: 277 | K9: JS
A10: 2 | B10: KETKI KILKARNI | C10: 27800409 | D10: 90 | E10: 3 | F10: 87 | G10: 5 | H10: 90 | I10: 2 | J10: 267 | K10: HO
A11: 3 | B11: SANKET SHIVAPUTRA BUKKANURE | C11: 27800015 | D11: 90 | E11: 3 | F11: 86 | G11: 6 | H11: 85 | I11: 6 | J11: 261 | K11: HO
A12: 4 | B12: KARTIK KULKARNI | C12: 27800404 | D12: 85 | E12: 12 | F12: 86 | G12: 6 | H12: 87 | I12: 5 | J12: 258 | K12: JS
A13: 5 | B13: SUMIT ANNASAHEB TAKADE | C13: 27800077 | D13: 87 | E13: 9 | F13: 83 | G13: 10 | H13: 77 | I13: 14 | J13: 247 | K13: JS
A14: 6 | B14: SATVIKA MORE | C14: 27800410 | D14: 76 | E14: 28 | F14: 90 | G14: 3 | H14: 81 | I14: 11 | J14: 247 | K14: HO
A15: 7 | B15: AISHWARJA BEHERA | C15: 27800050 | D15: 83 | E15: 16 | F15: 78 | G15: 16 | H15: 84 | I15: 7 | J15: 245 | K15: HO
A16: 8 | B16: ISHAAN PHADE | C16: 27900002 | D16: 91 | E16: 1 | F16: 77 | G16: 21 | H16: 75 | I16: 17 | J16: 243 | K16: PANDHARPUR
A17: 9 | B17: JAYRAJ HUGAR | C17: 27800405 | D17: 90 | E17: 3 | F17: 71 | G17: 41 | H17: 82 | I17: 9 | J17: 243 | K17: JS
A18: 10 | B18: OJAS HUMNABADKAR | C18: 27800408 | D18: 85 | E18: 12 | F18: 67 | G18: 62 | H18: 90 | I18: 2 | J18: 242 | K18: JS
A19: 11 | B19: PIYUSH PAWAR | C19: 27800406 | D19: 70 | E19: 36 | F19: 74 | G19: 32 | H19: 88 | I19: 4 | J19: 232 | K19: JS
A20: 12 | B20: RAJDEEP KHANDU GAIKWAD | C20: 27800056 | D20: 85 | E20: 12 | F20: 69 | G20: 50 | H20: 77 | I20: 14 | J20: 231 | K20: JS
... A97: 89 | B97: DHANUSH SALAGALA | C97: 27800413 | D97: 50 | E97: 81 | F97: 65 | G97: 78 | H97: 43 | I97: 132 | J97: 158 | K97: AC
A98: 90 | B98: SARTHAK KATEKAR | D98: 42 | E98: 99 | F98: 66 | G98: 70 | H98: 49 | I98: 100 | J98: 157 | K98: PANDHARPUR
A99: 91 | B99: RAJNANDINI PRAVIN KALKOTE | C99: 27800234 | D99: 26 | E99: 164 | F99: 62 | G99: 92 | H99: 67 | I99: 32 | J99: 155 | K99: HO
A100: 92 | B100: AMOL SIDDHARAM BHADANGE | C100: 27800165 | D100: 44 | E100: 94 | F100: 54 | G100: 155 | H100: 56 | I100: 69 | J100: 154 | K100: JS
A101: 93 | B101: VAINATEY KARCHE | C101: 27900038 | D101: 56 | E101: 64 | F101: 54 | G101: 155 | H101: 42 | I101: 137 | J101: 152 | K101: PANDHARPUR
A102: 94 | B102: VARAD VAIBHAV THOKAL | C102: 27800018 | D102: 53 | E102: 72 | F102: 39 | G102: 237 | H102: 58 | I102: 57 | J102: 150 | K102: JS
A103: 95 | B103: HARISHCHANDRA DETHE | C103: 27900025 | D103: 52 | E103: 76 | F103: 56 | G103: 134 | H103: 41 | I103: 141 | J103: 149 | K103: PANDHARPUR
A104: 96 | B104: SNEHA YADAV | C104: 27900031 | D104: 34 | E104: 124 | F104: 58 | G104: 123 | H104: 57 | I104: 61 | J104: 149 | K104: PANDHARPUR
A105: 97 | B105: VEDIKA KALBURGI | C105: 27800029 | D105: 44 | E105: 94 | F105: 69 | G105: 50 | H105: 36 | I105: 168 | J105: 149 | K105: JS
A106: 98 | B106: ATHARV AMOL CHINTAMANI | C106: 27800282 | D106: 45 | E106: 92 | F106: 56 | G106: 134 | H106: 48 | I106: 107 | J106: 149 | K106: JS
A107: 99 | B107: SHRUTI SHIVAJI KANHERE | C107: 27800308 | D107: 43 | E107: 96 | F107: 66 | G107: 70 | H107: 40 | I107: 148 | J107: 149 | K107: JS
A108: 100 | B108: GAYATRI BHAGYAWAN LOKHANDE | C108: 27800150 | D108: 19 | E108: 198 | F108: 75 | G108: 26 | H108: 55 | I108: 73 | J108: 149 | K108: HO
A109: 101 | B109: RUSHIKESH KATKAR | C109: 27900024 | D109: 51 | E109: 78 | F109: 62 | G109: 92 | H109: 34 | I109: 181 | J109: 147 | K109: PANDHARPUR
A110: 102 | B110: SHRIYASH JADHAV | C110: 27900029 | D110: 32 | E110: 133 | F110: 79 | G110: 14 | H110: 36 | I110: 168 | J110: 147 | K110: PANDHARPUR
... A141: 133 | B141: AMRUTA AUDHUMBAR CHAVRE | C141: 27800228 | D141: 29 | E141: 147 | F141: 72 | G141: 38 | H141: 29 | I141: 214 | J141: 130 | K141: JS
A142: 134 | B142: SOHAM KAVARE | D142: 40 | E142: 106 | F142: 42 | G142: 225 | H142: 47 | I142: 110 | J142: 129 | K142: PANDHARPUR
A143: 135 | B143: ADARSH BASAVRAJ NAROLE | C143: 27800082 | D143: 53 | E143: 72 | F143: 24 | G143: 296 | H143: 52 | I143: 88 | J143: 129 | K143: JS
A144: 136 | B144: AKSHATA AMAR SHINDE | C144: 27800046 | D144: 25 | E144: 169 | F144: 54 | G144: 155 | H144: 49 | I144: 100 | J144: 128 | K144: HO
A145: 137 | B145: AATMAN SANDIP KULKARNI | C145: 27800164 | D145: 47 | E145: 88 | F145: 42 | G145: 225 | H145: 39 | I145: 152 | J145: 128 | K145: JS
A146: 138 | B146: SHOURYA PURNENDU DHEPE | C146: 27800031 | D146: 29 | E146: 147 | F146: 46 | G146: 202 | H146: 53 | I146: 83 | J146: 128 | K146: JS
...

Sheet GRAND TEST-1 16TH AUG 25
A1: BAKLIWAL TUTORIALS
A2: JEE-2027 MAINS GRAND TEST - 01 RESULT 16TH AUGUST 2025
A3: TOP 122 STUDENTS IN THE SUBJECT
A4: 123 - 244 STUDENTS IN THE SUBJECT
A5: 245 - 367 STUDENTS IN THE SUBJECT
B6: MEDIAN MARKS | D6: 33 | F6: 42 | H6: 36 | J6: 113
B7: MAX | D7: 100 | F7: 100 | H7: 100 | J7: 300
A8: TOTAL RANK | B8: STUDENT NAME | C8: ROLL NO. | D8: PHY | E8: PHY RANK | F8: CHEM | G8: CHE RANK | H8: MATHS | I8: MATH RANK | J8: TOTAL | K8: BRANCH
A9: 1 | B9: ISHAN PHADE | C9: 27900002 | D9: 95 | E9: 2 | F9: 96 | G9: 1 | H9: 88 | I9: 11 | J9: 279 | K9: PANDHARPUR
A10: 2 | B10: KETKI KILKARNI | C10: 27800409 | D10: 85 | E10: 4 | F10: 82 | G10: 11 | H10: 100 | I10: 1 | J10: 267 | K10: HO
A11: 3 | B11: KARTIK KULKARNI | C11: 27800404 | D11: 100 | E11: 1 | F11: 86 | G11: 5 | H11: 76 | I11: 39 | J11: 262 | K11: JS
A12: 4 | B12: ARYAN SHAMKUMAR DESHMUKH | C12: 27800016 | D12: 85 | E12: 4 | F12: 81 | G12: 14 | H12: 85 | I12: 14 | J12: 251 | K12: JS
A13: 5 | B13: YATHARTH APPASAHEB PATIL | C13: 27800014 | D13: 70 | E13: 26 | F13: 90 | G13: 4 | H13: 90 | I13: 8 | J13: 250 | K13: HO
A14: 6 | B14: RAJDEEP KHANDU GAIKWAD | C14: 27800056 | D14: 81 | E14: 10 | F14: 86 | G14: 5 | H14: 82 | I14: 20 | J14: 249 | K14: JS
A15: 7 | B15: OJAS HUMNABADKAR | C15: 27800408 | D15: 75 | E15: 18 | F15: 81 | G15: 14 | H15: 90 | I15: 8 | J15: 246 | K15: JS
A16: 8 | B16: GIRISH VITHAL NARANGKAR | C16: 27800202 | D16: 78 | E16: 15 | F16: 86 | G16: 5 | H16: 80 | I16: 27 | J16: 244 | K16: HO
A17: 9 | B17: SUMIT ANNASAHEB TAKADE | C17: 27800077 | D17: 80 | E17: 13 | F17: 73 | G17: 32 | H17: 91 | I17: 6 | J17: 244 | K17: JS
A18: 10 | B18: PRAGUN VINEET RATHI | C18: 27800167 | D18: 76 | E18: 17 | F18: 95 | G18: 2 | H18: 72 | I18: 52 | J18: 243 | K18: HO
A19: 11 | B19: ANIMESH CHAVAN | C19: 27800403 | D19: 86 | E19: 3 | F19: 81 | G19: 14 | H19: 76 | I19: 39 | J19: 243 | K19: JS
A20: 12 | B20: ARJUN RANJEET PATIL | C20: 27800035 | D20: 81 | E20: 10 | F20: 86 | G20: 5 | H20: 72 | I20: 52 | J20: 239 | K20: JS
... A375: 367 | B375: MADIHA FIRDOS SHAIKH | C375: 27800264 | D375: -2 | E375: 355 | F375: 12 | G375: 330 | H375: -10 | I375: 367 | J375: 0 | K375: HO
A376: STUDENTS WHOSE NAMES ARE NOT IN RANK LIST,WERE ABSENT FOR THE TEST

Sheet BTEST414TH SEPT 25
A1: BAKLIWAL TUTORIALS
A2: JEE-2027 MAINS BTEST-04 RESULT 14 SEPTEMBER 2025
A3: TOP 107 STUDENTS IN THE SUBJECT
A4: 108 - 214 STUDENTS IN THE SUBJECT
A5: 215 - 322 STUDENTS IN THE SUBJECT
B6: MEDIAN MARKS | D6: 40 | F6: 43.5 | H6: 28 | J6: 106
B7: MAX | D7: 100 | F7: 100 | H7: 100 | J7: 300
A8: TOTAL RANK | B8: STUDENT NAME | C8: ROLL NO. | D8: PHY | E8: PHY RANK | F8: CHEM | G8: CHE RANK | H8: MATHS | I8: MATH RANK | J8: TOTAL | K8: BRANCH | L8: BATCH
A9: 1 | B9: ISHAN PHADE | C9: 27353204 | D9: 91 | E9: 3 | F9: 95 | G9: 4 | H9: 100 | I9: 1 | J9: 286 | K9: PANDHARPUR
A10: 2 | B10: KETKI KULKARNI | C10: 27800409 | D10: 95 | E10: 2 | F10: 100 | G10: 1 | H10: 87 | I10: 4 | J10: 282 | K10: JS | L10: WOW
A11: 3 | B11: PIYUSH PAWAR | C11: 27800406 | D11: 85 | E11: 12 | F11: 100 | G11: 1 | H11: 90 | I11: 3 | J11: 275 | K11: JS
A12: 4 | B12: OJAS HUMNABADKAR | C12: 27800408 | D12: 90 | E12: 5 | F12: 80 | G12: 27 | H12: 100 | I12: 1 | J12: 270 | K12: JS | L12: WOW
A13: 5 | B13: KARTIK KULKARNI | C13: 27800404 | D13: 90 | E13: 5 | F13: 100 | G13: 1 | H13: 79 | I13: 11 | J13: 269 | K13: JS | L13: WOW
A14: 6 | B14: RAJDEEP KHANDU GAIKWAD | C14: 27343132 | D14: 96 | E14: 1 | F14: 91 | G14: 6 | H14: 79 | I14: 11 | J14: 266 | K14: JS | L14: WOW
A15: 7 | B15: SATVIKA MORE | C15: 27800410 | D15: 87 | E15: 9 | F15: 91 | G15: 6 | H15: 87 | I15: 4 | J15: 265 | K15: JS | L15: WOW
A16: 8 | B16: SUMIT ANNASAHEB TAKADE | C16: 27371780 | D16: 86 | E16: 11 | F16: 91 | G16: 6 | H16: 84 | I16: 8 | J16: 261 | K16: JS | L16: WOW
A17: 9 | B17: ANIMESH CHAVAN | C17: 27800403 | D17: 90 | E17: 5 | F17: 90 | G17: 9 | H17: 72 | I17: 17 | J17: 252 | K17: JS | L17: WOW
A18: 10 | B18: PRAGUN VINEET RATHI | C18: 27343975 | D18: 82 | E18: 17 | F18: 95 | G18: 4 | H18: 74 | I18: 16 | J18: 251 | K18: JS | L18: WOW
A19: 11 | B19: HARSHVARDHAN CHOUDHARI | C19: 27338488 | D19: 72 | E19: 40 | F19: 87 | G19: 11 | H19: 87 | I19: 4 | J19: 246 | K19: JS | L19: WOW
A20: 12 | B20: ARYAN SHAMKUMAR DESHMUKH | C20: 27343303 | D20: 85 | E20: 12 | F20: 75 | G20: 43 | H20: 85 | I20: 7 | J20: 245 | K20: JS | L20: WOW
A21: 13 | B21: OJAS AKASH REPAL | C21: 26850028 | D21: 88 | E21: 8 | F21: 78 | G21: 29 | H21: 78 | I21: 13 | J21: 244 | K21: JS | L21: WOW
A22: 14 | B22: JAYRAJ HUGAR | C22: 27800405 | D22: 78 | E22: 27 | F22: 90 | G22: 9 | H22: 75 | I22: 14 | J22: 243 | K22: JS | L22: WOW
A23: 15 | B23: SANKET SHIVAPUTRA BUKKANURE | C23: 27333715 | D23: 85 | E23: 12 | F23: 85 | G23: 16 | H23: 70 | I23: 20 | J23: 240 | K23: JS | L23: WOW
A24: 16 | B24: AKHILESH GAIKWAD | C24: 27800407 | D24: 73 | E24: 38 | F24: 86 | G24: 13 | H24: 81 | I24: 10 | J24: 240 | K24: JS
A25: 17 | B25: AVADHOOT KULKARNI | C25: 27361589 | D25: 81 | E25: 22 | F25: 85 | G25: 16 | H25: 71 | I25: 19 | J25: 237 | K25: JS | L25: WOW
A26: 18 | B26: VARAD MALANI | C26: 27194907 | D26: 80 | E26: 24 | F26: 86 | G26: 13 | H26: 70 | I26: 20 | J26: 236 | K26: JS | L26: WOW
A27: 19 | B27: YATHARTH YADAV | C27: 27362914 | D27: 82 | E27: 17 | F27: 68 | G27: 65 | H27: 82 | I27: 9 | J27: 232 | K27: JS | L27: WOW
A28: 20 | B28: SHREYA ANIL ANKOLKAR | C28: 27358598 | D28: 87 | E28: 9 | F28: 78 | G28: 29 | H28: 66 | I28: 24 | J28: 231 | K28: JS | L28: WOW
A29: 21 | B29: ANUJ MANOJ JADHAV | C29: 27372856 | D29: 74 | E29: 35 | F29: 87 | G29: 11 | H29: 63 | I29: 34 | J29: 224 | K29: JS | L29: WIZ
A30: 22 | B30: SHRAVNI ARVIND GIRAM | C30: 27337339 | D30: 81 | E30: 22 | F30: 81 | G30: 26 | H30: 60 | I30: 41 | J30: 222 | K30: JS | L30: WOW
A31: 23 | B31: SAMRUDDHI RAJENDRAKUMAR KOLEKAR | C31: 27368316 | D31: 80 | E31: 24 | F31: 85 | G31: 16 | H31: 54 | I31: 54 | J31: 219 | K31: JS | L31: WOW
A32: 24 | B32: MADHAVI SATALINGAPPA DHODAMANI | C32: 27269367 | D32: 72 | E32: 40 | F32: 82 | G32: 24 | H32: 64 | I32: 28 | J32: 218 | K32: HO | L32: WIZ
A33: 25 | B33: SHREYA CHITNIS | C33: 27352438 | D33: 82 | E33: 17 | F33: 78 | G33: 29 | H33: 57 | I33: 49 | J33: 217 | K33: PANDHARPUR
A34: 26 | B34: VAISHNAVI VAIBHAV MORE | C34: 27344697 | D34: 72 | E34: 40 | F34: 83 | G34: 22 | H34: 61 | I34: 38 | J34: 216 | K34: JS | L34: WOW
A35: 27 | B35: TRISHA SHANKAR BHANDARI | C35: 27350345 | D35: 79 | E35: 26 | F35: 63 | G35: 85 | H35: 72 | I35: 17 | J35: 214 | K35: JS | L35: WOW
A36: 28 | B36: YASH SANTOSH BHAJIBHAKARE | C36: 27332994 | D36: 68 | E36: 52 | F36: 85 | G36: 16 | H36: 59 | I36: 44 | J36: 212 | K36: JS | L36: WIZ
A37: 29 | B37: VEDIKA REVANSIDDHA ANDHALKAR | C37: 27380101 | D37: 83 | E37: 15 | F37: 76 | G37: 40 | H37: 53 | I37: 57 | J37: 212 | K37: JS | L37: WOW
A38: 30 | B38: ARYAN SACHIN BHOSALE | C38: 27358884 | D38: 82 | E38: 17 | F38: 75 | G38: 43 | H38: 55 | I38: 52 | J38: 212 | K38: JS | L38: WOW
A39: 31 | B39: KOMAL SATISH PEGADA | C39: 27361800 | D39: 68 | E39: 52 | F39: 86 | G39: 13 | H39: 58 | I39: 46 | J39: 212 | K39: AC
A40: 32 | B40: SHUBHRA VILAS SARVADE | C40: 27358279 | D40: 72 | E40: 40 | F40: 75 | G40: 43 | H40: 64 | I40: 28 | J40: 211 | K40: JS | L40: WOW
...

Sheet BTEST-512TH OCT 25
D1: BAKLIWAL TUTORIALS
D2: JEE-2027 MAINS BTEST-05 RESULT 12 OCTOBER 2025
D3: TOP 114 STUDENTS IN THE SUBJECT
D4: 115- 228 STUDENTS IN THE SUBJECT
D5: 229 - 342 STUDENTS IN THE SUBJECT
E6: MEDIAN MARKS | G6: 43 | I6: 47 | K6: 21 | M6: 114
E7: MAX | G7: 100 | I7: 100 | K7: 100 | M7: 300
D8: TOTAL RANK | E8: STUDENT NAME | F8: ROLL NO. | G8: PHY | H8: PHY RANK | I8: CHEM | J8: CHE RANK | K8: MATHS | L8: MATH RANK | M8: TOTAL | N8: BRANCH | O8: BATCH
D9: 1 | E9: KARTIK KULKARNI | F9: 27800404 | G9: 95 | H9: 1 | I9: 76 | J9: 25 | K9: 72 | L9: 3 | M9: 243 | N9: JS | O9: WOW
D10: 2 | E10: ISHAN PHADE | F10: 27353204 | G10: 78 | H10: 10 | I10: 92 | J10: 1 | K10: 71 | L10: 4 | M10: 241 | N10: PANDHARPUR
D11: 3 | E11: JAYRAJ HUGAR | F11: 27800405 | G11: 83 | H11: 4 | I11: 91 | J11: 3 | K11: 66 | L11: 6 | M11: 240 | N11: JS | O11: WOW
D12: 4 | E12: KETKI KULKARNI | F12: 27800409 | G12: 91 | H12: 2 | I12: 71 | J12: 48 | K12: 69 | L12: 5 | M12: 231 | N12: JS | O12: WOW
D13: 5 | E13: OJAS AKASH REPAL | F13: 26850028 | G13: 69 | H13: 25 | I13: 83 | J13: 15 | K13: 75 | L13: 1 | M13: 227 | N13: JS | O13: WOW
D14: 6 | E14: ANIMESH CHAVAN | F14: 27800403 | G14: 87 | H14: 3 | I14: 86 | J14: 12 | K14: 53 | L14: 19 | M14: 226 | N14: JS | O14: WOW
D15: 7 | E15: PIYUSH PAWAR | F15: 27800406 | G15: 76 | H15: 12 | I15: 86 | J15: 12 | K15: 59 | L15: 11 | M15: 221 | N15: JS
D16: 8 | E16: AKHILESH GAIKWAD | F16: 27800407 | G16: 70 | H16: 22 | I16: 76 | J16: 25 | K16: 74 | L16: 2 | M16: 220 | N16: JS | O16: WOW
D17: 9 | E17: PRAGUN VINEET RATHI | F17: 27343975 | G17: 83 | H17: 4 | I17: 82 | J17: 16 | K17: 53 | L17: 19 | M17: 218 | N17: JS | O17: WOW
D18: 10 | E18: HARSHVARDHAN CHOUDHARI | F18: 27338488 | G18: 79 | H18: 9 | I18: 82 | J18: 16 | K18: 56 | L18: 17 | M18: 217 | N18: JS | O18: WOW
D19: 11 | E19: ARNAV THITE | F19: 26850027 | G19: 69 | H19: 25 | I19: 87 | J19: 7 | K19: 60 | L19: 9 | M19: 216 | N19: PANDHARPUR
D20: 12 | E20: OJAS HUMNABADKAR | F20: 27800408 | G20: 81 | H20: 8 | I20: 87 | J20: 7 | K20: 48 | L20: 32 | M20: 216 | N20: JS | O20: WOW
D21: 13 | E21: VEDASHRI NAGNATH MUNGAPATIL | F21: 27377476 | G21: 67 | H21: 31 | I21: 77 | J21: 24 | K21: 64 | L21: 7 | M21: 208 | N21: AC
D22: 14 | E22: SUMIT ANNASAHEB TAKADE | F22: 27371780 | G22: 68 | H22: 27 | I22: 82 | J22: 16 | K22: 58 | L22: 14 | M22: 208 | N22: JS | O22: WOW
D23: 15 | E23: RAJDEEP KHANDU GAIKWAD | F23: 27343132 | G23: 83 | H23: 4 | I23: 74 | J23: 36 | K23: 50 | L23: 23 | M23: 207 | N23: JS | O23: WOW
D24: 16 | E24: VARAD MALANI | F24: 27194907 | G24: 73 | H24: 16 | I24: 81 | J24: 20 | K24: 48 | L24: 32 | M24: 202 | N24: JS | O24: WOW
D25: 17 | E25: SANKET SHIVAPUTRA BUKKANURE | F25: 27333715 | G25: 70 | H25: 22 | I25: 70 | J25: 51 | K25: 60 | L25: 9 | M25: 200 | N25: JS | O25: WOW
D26: 18 | E26: SURYAANSH SHRINIWAS CHIPPA | F26: 27363118 | G26: 72 | H26: 17 | I26: 92 | J26: 1 | K26: 36 | L26: 78 | M26: 200 | N26: HO | O26: WIZ
D27: 19 | E27: SHRAVNI ARVIND GIRAM | F27: 27337339 | G27: 78 | H27: 10 | I27: 68 | J27: 59 | K27: 50 | L27: 23 | M27: 196 | N27: JS | O27: WOW
D28: 20 | E28: ARYAN SACHIN BHOSALE | F28: 27358884 | G28: 72 | H28: 17 | I28: 86 | J28: 12 | K28: 37 | L28: 73 | M28: 195 | N28: JS | O28: WOW
D29: 21 | E29: GIRISH VITHAL NARANGKAR | F29: 27377063 | G29: 55 | H29: 87 | I29: 87 | J29: 7 | K29: 52 | L29: 21 | M29: 194 | N29: JS | O29: WOW
D30: 22 | E30: YATHARTH APPASAHEB PATIL | F30: 27344511 | G30: 53 | H30: 99 | I30: 91 | J30: 3 | K30: 47 | L30: 36 | M30: 191 | N30: JS | O30: WOW
D31: 23 | E31: SHREYA VIJAYKUMAR BIRADAR | F31: 27340955 | G31: 55 | H31: 87 | I31: 72 | J31: 43 | K31: 64 | L31: 7 | M31: 191 | N31: JS | O31: WOW
D32: 24 | E32: NEIL SHIVRAJ SHRIRAM | F32: 27380936 | G32: 53 | H32: 99 | I32: 87 | J32: 7 | K32: 48 | L32: 32 | M32: 188 | N32: HO | O32: WIZ
D33: 25 | E33: ANNAPURANA SHAILENDRA KANAKI | F33: 27361678 | G33: 52 | H33: 109 | I33: 87 | J33: 7 | K33: 49 | L33: 26 | M33: 188 | N33: AC
D34: 26 | E34: ARJUN RANJEET PATIL | F34: 27340819 | G34: 75 | H34: 14 | I34: 81 | J34: 20 | K34: 31 | L34: 105 | M34: 187 | N34: JS | O34: WOW
D35: 27 | E35: AKSHARA KOTHARI | F35: 27357834 | G35: 61 | H35: 54 | I35: 91 | J35: 3 | K35: 35 | L35: 89 | M35: 187 | N35: PANDHARPUR
D36: 28 | E36: AKSHATA SUDARSHAN KARAJGIKAR | F36: 27336079 | G36: 68 | H36: 27 | I36: 70 | J36: 51 | K36: 49 | L36: 26 | M36: 187 | N36: JS | O36: WOW
D37: 29 | E37: AVANTI ANIL JAGTAP | F37: 27346925 | G37: 72 | H37: 17 | I37: 68 | J37: 59 | K37: 47 | L37: 36 | M37: 187 | N37: JS | O37: WOW
D38: 30 | E38: TRISHA SHANKAR BHANDARI | F38: 27350345 | G38: 72 | H38: 17 | I38: 74 | J38: 36 | K38: 40 | L38: 60 | M38: 186 | N38: JS | O38: WOW
D39: 31 | E39: AISHWARJA BEHERA | F39: 27356474 | G39: 68 | H39: 27 | I39: 74 | J39: 36 | K39: 43 | L39: 46 | M39: 185 | N39: JS | O39: WOW
D40: 32 | E40: VEDIKA REVANSIDDHA ANDHALKAR | F40: 27380101 | G40: 66 | H40: 35 | I40: 76 | J40: 25 | K40: 43 | L40: 46 | M40: 185 | N40: JS | O40: WOW
...

Sheet BTEST-616TH NOV 25
A1: BAKLIWAL TUTORIALS
A2: JEE-2027 MAINS BTEST - 06 RESULT 16 NOVEMBER 2025
A3: TOP 112 STUDENTS IN THE SUBJECT
A4: 113 - 224 STUDENTS IN THE SUBJECT
A5: 225 - 337 STUDENTS IN THE SUBJECT
B6: MEDIAN MARKS | D6: 41 | F6: 46 | H6: 33 | J6: 120
B7: MAX | D7: 100 | F7: 100 | H7: 100 | J7: 300
A8: TOTAL RANK | B8: STUDENT NAME | C8: ROLL NO. | D8: PHY | E8: PHY RANK | F8: CHEM | G8: CHE RANK | H8: MATHS | I8: MATH RANK | J8: TOTAL | K8: BRANCH | L8: BATCH
A9: 1 | B9: KARTIK KULKARNI | C9: 27800404 | D9: 100 | E9: 1 | F9: 80 | G9: 18 | H9: 92 | I9: 1 | J9: 272 | K9: SOLAPUR | L9: WOW
A10: 2 | B10: JAYRAJ HUGAR | C10: 27800405 | D10: 88 | E10: 7 | F10: 96 | G10: 1 | H10: 83 | I10: 5 | J10: 267 | L10: WOW
A11: 3 | B11: SANKET SHIVAPUTRA BUKKANURE | C11: 27333715 | D11: 85 | E11: 10 | F11: 95 | G11: 2 | H11: 85 | I11: 4 | J11: 265 | K11: SOLAPUR | L11: WOW
A12: 4 | B12: ANIMESH CHAVAN | C12: 27800403 | D12: 91 | E12: 2 | F12: 90 | G12: 5 | H12: 83 | I12: 5 | J12: 264 | K12: SOLAPUR | L12: WOW
A13: 5 | B13: ISHAN PHADE | C13: 27353204 | D13: 91 | E13: 2 | F13: 91 | G13: 3 | H13: 78 | I13: 11 | J13: 260 | K13: PANDHARPUR
A14: 6 | B14: SUMIT ANNASAHEB TAKADE | C14: 27371780 | D14: 82 | E14: 15 | F14: 88 | G14: 7 | H14: 88 | I14: 3 | J14: 258 | K14: SOLAPUR | L14: WOW
A15: 7 | B15: KETKI KULKARNI | C15: 27800409 | D15: 76 | E15: 25 | F15: 86 | G15: 9 | H15: 92 | I15: 1 | J15: 254 | K15: SOLAPUR | L15: WOW
A16: 8 | B16: RAJDEEP KHANDU GAIKWAD | C16: 27343132 | D16: 81 | E16: 17 | F16: 91 | G16: 3 | H16: 79 | I16: 9 | J16: 251 | K16: SOLAPUR | L16: WOW
A17: 9 | B17: AKSHARA KOTHARI | C17: 27357834 | D17: 83 | E17: 13 | F17: 80 | G17: 18 | H17: 83 | I17: 5 | J17: 246 | K17: PANDHARPUR
A18: 10 | B18: ARYAN SHAMKUMAR DESHMUKH | C18: 27343303 | D18: 85 | E18: 10 | F18: 80 | G18: 18 | H18: 81 | I18: 8 | J18: 246 | K18: SOLAPUR | L18: WOW
A19: 11 | B19: PRAGUN VINEET RATHI | C19: 27343975 | D19: 86 | E19: 9 | F19: 90 | G19: 5 | H19: 69 | I19: 30 | J19: 245 | K19: SOLAPUR | L19: WOW
A20: 12 | B20: VEDIKA REVANSIDDHA ANDHALKAR | C20: 27380101 | D20: 81 | E20: 17 | F20: 86 | G20: 9 | H20: 75 | I20: 19 | J20: 242 | K20: SOLAPUR | L20: WOW
A21: 13 | B21: AKHILESH GAIKWAD | C21: 27800407 | D21: 78 | E21: 23 | F21: 83 | G21: 13 | H21: 78 | I21: 11 | J21: 239 | K21: SOLAPUR | L21: WOW
A22: 14 | B22: AVADHOOT KULKARNI | C22: 27361589 | D22: 90 | E22: 4 | F22: 85 | G22: 12 | H22: 62 | I22: 44 | J22: 237 | K22: SOLAPUR | L22: WOW
A23: 15 | B23: SATVIKA MORE | C23: 27800410 | D23: 82 | E23: 15 | F23: 75 | G23: 33 | H23: 79 | I23: 9 | J23: 236 | K23: SOLAPUR | L23: WOW
A24: 16 | B24: ARJUN RANJEET PATIL | C24: 27340819 | D24: 87 | E24: 8 | F24: 74 | G24: 35 | H24: 69 | I24: 30 | J24: 230 | K24: SOLAPUR | L24: WOW
A25: 17 | B25: SHREYA CHITNIS | C25: 27352438 | D25: 77 | E25: 24 | F25: 70 | G25: 52 | H25: 78 | I25: 11 | J25: 225 | K25: PANDHARPUR
A26: 18 | B26: AAMEYA DADPE | C26: 27800401 | D26: 74 | E26: 27 | F26: 73 | G26: 40 | H26: 78 | I26: 11 | J26: 225 | K26: SOLAPUR | L26: WOW
A27: 19 | B27: YATHARTH APPASAHEB PATIL | C27: 27344511 | D27: 85 | E27: 10 | F27: 81 | G27: 17 | H27: 58 | I27: 57 | J27: 224 | K27: SOLAPUR | L27: WOW
A28: 20 | B28: SHRAVNI ARVIND GIRAM | C28: 27337339 | D28: 68 | E28: 44 | F28: 86 | G28: 9 | H28: 68 | I28: 32 | J28: 222 | K28: SOLAPUR | L28: WOW
A29: 21 | B29: AKSHATA SUDARSHAN KARAJGIKAR | C29: 27336079 | D29: 80 | E29: 21 | F29: 80 | G29: 18 | H29: 62 | I29: 44 | J29: 222 | K29: SOLAPUR | L29: WOW
A30: 22 | B30: ARYAN SADIGALE | C30: 27355192 | D30: 90 | E30: 4 | F30: 70 | G30: 52 | H30: 60 | I30: 51 | J30: 220 | K30: PANDHARPUR
A31: 23 | B31: SHREYA VIJAYKUMAR BIRADAR | C31: 27340955 | D31: 66 | E31: 50 | F31: 80 | G31: 18 | H31: 72 | I31: 24 | J31: 218 | K31: SOLAPUR | L31: WOW
A32: 24 | B32: OJAS HUMNABADKAR | C32: 27800408 | D32: 81 | E32: 17 | F32: 78 | G32: 25 | H32: 58 | I32: 57 | J32: 217
A33: 25 | B33: ANANYA GOVIND ANAGUNDE | C33: 27339321 | D33: 67 | E33: 46 | F33: 75 | G33: 33 | H33: 74 | I33: 21 | J33: 216 | K33: SOLAPUR | L33: WOW
A34: 26 | B34: KUNJAL MANIYAR | C34: 27353386 | D34: 73 | E34: 29 | F34: 77 | G34: 30 | H34: 65 | I34: 36 | J34: 215 | K34: PANDHARPUR
A35: 27 | B35: ARNAV THITE | C35: 26850027 | D35: 83 | E35: 13 | F35: 78 | G35: 25 | H35: 53 | I35: 74 | J35: 214 | K35: PANDHARPUR
A36: 28 | B36: PIYUSH PAWAR | C36: 27800406 | D36: 65 | E36: 52 | F36: 73 | G36: 40 | H36: 75 | I36: 19 | J36: 213 | K36: SOLAPUR
A37: 29 | B37: ADESH SOPAN PARDE | C37: 27380580 | D37: 69 | E37: 40 | F37: 70 | G37: 52 | H37: 74 | I37: 21 | J37: 213 | K37: SOLAPUR | L37: WIZ
A38: 30 | B38: SRUSHTI RAJENDRA GHADAGE | C38: 27362786 | D38: 66 | E38: 50 | F38: 74 | G38: 35 | H38: 72 | I38: 24 | J38: 212 | K38: SOLAPUR | L38: WOW
A39: 31 | B39: OJAS AKASH REPAL | C39: 26850028 | D39: 64 | E39: 55 | F39: 72 | G39: 45 | H39: 76 | I39: 16 | J39: 212 | K39: SOLAPUR | L39: WOW
A40: 32 | B40: AMOL SIDDHARAM BHADANGE | C40: 27370899 | D40: 81 | E40: 17 | F40: 62 | G40: 83 | H40: 65 | I40: 36 | J40: 208 | K40: SOLAPUR | L40: WIZ
...

Sheet GRAND TEST-213TH DEC 25
A1: BAKLIWAL TUTORIALS
A2: JEE-2027 MAINS GRAND TEST - 02 RESULT 13TH DECEMBER 2025
A3: TOP 115 STUDENTS IN THE SUBJECT
A4: 116 - 230 STUDENTS IN THE SUBJECT
A5: 231 - 345 STUDENTS IN THE SUBJECT
B6: MEDIAN MARKS | D6: 41 | F6: 40 | H6: 22 | J6: 105
B7: MAX | D7: 100 | F7: 100 | H7: 100 | J7: 300
A8: TOTAL RANK | B8: STUDENT NAME | C8: ROLL NO. | D8: PHY | E8: PHY RANK | F8: CHEM | G8: CHE RANK | H8: MATHS | I8: MATH RANK | J8: TOTAL | K8: BRANCH | L8: BATCH
A9: 1 | B9: ISHAN PHADE | C9: 27353204 | D9: 81 | E9: 3 | F9: 91 | G9: 2 | H9: 72 | I9: 3 | J9: 244 | K9: PANDHARPUR
A10: 2 | B10: KARTIK KULKARNI | C10: 27800404 | D10: 85 | E10: 1 | F10: 82 | G10: 9 | H10: 69 | I10: 7 | J10: 236 | K10: JS | L10: WOW
A11: 3 | B11: AKHILESH GAIKWAD | C11: 27800407 | D11: 77 | E11: 7 | F11: 85 | G11: 7 | H11: 68 | I11: 8 | J11: 230 | K11: JS | L11: WOW
A12: 4 | B12: JAYRAJ HUGAR | C12: 27800405 | D12: 77 | E12: 7 | F12: 91 | G12: 2 | H12: 61 | I12: 16 | J12: 229 | K12: JS | L12: WOW
A13: 5 | B13: SANKET SHIVAPUTRA BUKKANURE | C13: 27333715 | D13: 75 | E13: 12 | F13: 80 | G13: 14 | H13: 71 | I13: 5 | J13: 226 | K13: JS | L13: WOW
A14: 6 | B14: PRAGUN VINEET RATHI | C14: 27343975 | D14: 78 | E14: 6 | F14: 81 | G14: 12 | H14: 65 | I14: 12 | J14: 224 | K14: JS | L14: WOW
A15: 7 | B15: RAJDEEP KHANDU GAIKWAD | C15: 27343132 | D15: 81 | E15: 3 | F15: 79 | G15: 16 | H15: 64 | I15: 15 | J15: 224 | K15: JS | L15: WOW
A16: 8 | B16: SHRAVNI ARVIND GIRAM | C16: 27337339 | D16: 74 | E16: 13 | F16: 83 | G16: 8 | H16: 65 | I16: 12 | J16: 222 | K16: JS | L16: WOW
A17: 9 | B17: YATHARTH APPASAHEB PATIL | C17: 27344511 | D17: 71 | E17: 28 | F17: 81 | G17: 12 | H17: 68 | I17: 8 | J17: 220 | K17: JS | L17: WOW
A18: 10 | B18: KETKI KULKARNI | C18: 27800409 | D18: 76 | E18: 11 | F18: 78 | G18: 18 | H18: 65 | I18: 12 | J18: 219 | K18: JS | L18: WOW
A19: 11 | B19: SUMIT ANNASAHEB TAKADE | C19: 27371780 | D19: 73 | E19: 16 | F19: 78 | G19: 18 | H19: 67 | I19: 10 | J19: 218 | K19: JS | L19: WOW
A20: 12 | B20: ANIMESH CHAVAN | C20: 27800403 | D20: 71 | E20: 28 | F20: 87 | G20: 6 | H20: 58 | I20: 19 | J20: 216 | K20: JS | L20: WOW
A21: 13 | B21: OJAS HUMNABADKAR | C21: 27800408 | D21: 65 | E21: 56 | F21: 76 | G21: 24 | H21: 73 | I21: 2 | J21: 214 | K21: JS | L21: WOW
A22: 14 | B22: ARNAV THITE | C22: 26850027 | D22: 73 | E22: 16 | F22: 88 | G22: 5 | H22: 51 | I22: 34 | J22: 212 | K22: PANDHARPUR
A23: 15 | B23: SURYAANSH SHRINIWAS CHIPPA | C23: 27363118 | D23: 73 | E23: 16 | F23: 69 | G23: 46 | H23: 67 | I23: 10 | J23: 209 | K23: HO | L23: WIZ
A24: 16 | B24: GIRISH VITHAL NARANGKAR | C24: 27377063 | D24: 77 | E24: 7 | F24: 76 | G24: 24 | H24: 53 | I24: 28 | J24: 206 | K24: JS | L24: WOW
A25: 17 | B25: ARYAN SHAMKUMAR DESHMUKH | C25: 27343303 | D25: 70 | E25: 36 | F25: 82 | G25: 9 | H25: 52 | I25: 31 | J25: 204 | K25: JS | L25: WOW
A26: 18 | B26: VEDIKA REVANSIDDHA ANDHALKAR | C26: 27380101 | D26: 63 | E26: 62 | F26: 92 | G26: 1 | H26: 48 | I26: 47 | J26: 203 | K26: JS | L26: WOW
A27: 19 | B27: PRATHEMESH BADAVE | C27: 27355088 | D27: 62 | E27: 68 | F27: 91 | G27: 2 | H27: 49 | I27: 41 | J27: 202 | K27: PANDHARPUR
A28: 20 | B28: SHAURYA BORGAVKAR | C28: 27374439 | D28: 71 | E28: 28 | F28: 77 | G28: 22 | H28: 54 | I28: 25 | J28: 202 | K28: PANDHARPUR
A29: 21 | B29: AKSHATA SUDARSHAN KARAJGIKAR | C29: 27336079 | D29: 68 | E29: 42 | F29: 73 | G29: 39 | H29: 60 | I29: 17 | J29: 201 | K29: JS | L29: WOW
A30: 22 | B30: OJAS AKASH REPAL | C30: 26850028 | D30: 58 | E30: 91 | F30: 82 | G30: 9 | H30: 60 | I30: 17 | J30: 200 | K30: JS | L30: WOW
A31: 23 | B31: PIYUSH PAWAR | C31: 27800406 | D31: 63 | E31: 62 | F31: 65 | G31: 65 | H31: 72 | I31: 3 | J31: 200 | K31: JS
A32: 24 | B32: SHREYA ANIL ANKOLIKAR | C32: 27358598 | D32: 63 | E32: 62 | F32: 64 | G32: 66 | H32: 70 | I32: 6 | J32: 197 | K32: JS | L32: WOW
A33: 25 | B33: AKSHARA KOTHARI | C33: 27357834 | D33: 73 | E33: 16 | F33: 76 | G33: 24 | H33: 48 | I33: 47 | J33: 197 | K33: PANDHARPUR
A34: 26 | B34: AVADHOOT KULKARNI | C34: 27361589 | D34: 71 | E34: 28 | F34: 75 | G34: 30 | H34: 50 | I34: 38 | J34: 196 | K34: JS | L34: WOW
A35: 27 | B35: VARAD MALANI | C35: 27194907 | D35: 62 | E35: 68 | F35: 75 | G35: 30 | H35: 57 | I35: 21 | J35: 194 | K35: JS | L35: WOW
A36: 28 | B36: YATHARTH YADAV | C36: 27362914 | D36: 71 | E36: 28 | F36: 78 | G36: 18 | H36: 44 | I36: 67 | J36: 193 | K36: JS | L36: WOW
A37: 29 | B37: HARSHADA SUSHILKUMAR EKBOTE | C37: 27360150 | D37: 72 | E37: 23 | F37: 68 | G37: 50 | H37: 51 | I37: 34 | J37: 191 | K37: AC
A38: 30 | B38: ARUSH AJIT KULKARNI | C38: 27109976 | D38: 61 | E38: 74 | F38: 71 | G38: 44 | H38: 57 | I38: 21 | J38: 189 | K38: JS | L38: WOW
A39: 31 | B39: VAISHNAVI VAIBHAV MORE | C39: 27344697 | D39: 73 | E39: 16 | F39: 69 | G39: 46 | H39: 47 | I39: 52 | J39: 189 | K39: JS | L39: WOW
A40: 32 | B40: TRISHA SHANKAR BHANDARI | C40: 27350345 | D40: 73 | E40: 16 | F40: 68 | G40: 50 | H40: 47 | I40: 52 | J40: 188 | K40: JS | L40: WOW
...

Sheet BRTEST-128 DEC 25
A1: BAKLIWAL TUTORIALS
A2: JEE - 2027 BRTEST - 01 (CET FORMAT) RESULT 28 DECEMBER 2025
A3: TOP 99 STUDENT IN THE SUBJECT
A4: 100 -198 STUDENT IN THE SUBJECT
A5: 199 - 297 STUDENT IN THE SUBJECT
B6: MEDIAN MARKS | D6: 21 | F6: 24 | H6: 72 | J6: 91
B7: MAX | D7: 50 | F7: 50 | H7: 100 | J7: 200
A8: TOTAL RANK | B8: STUDENT NAME | C8: ROLL NO | D8: PHY | E8: PHY RANK | F8: CHEM | G8: CHE RANK | H8: MATHS | I8: MATH RANK | J8: TOTAL | K8: BRANCH | L8: BATCH
A9: 1 | B9: KETKI KULKARNI | C9: 23000010 | D9: 42 | E9: 7 | F9: 49 | G9: 1 | H9: 90 | I9: 3 | J9: 181 | K9: JS | L9: =VLOOKUP(C9,Sheet20!$C$2:$D$279,2,0) -> WOW
A10: 2 | B10: ANIMESH CHAVAN | C10: 23000004 | D10: 44 | E10: 1 | F10: 40 | G10: 6 | H10: 92 | I10: 1 | J10: 176 | K10: JS | L10: =VLOOKUP(C10,Sheet20!$C$2:$D$279,2,0) -> WOW
A11: 3 | B11: SANKET SHIVAPUTRA BUKKANURE | C11: 27333715 | D11: 36 | E11: 22 | F11: 43 | G11: 2 | H11: 90 | I11: 3 | J11: 169 | K11: JS | L11: =VLOOKUP(C11,Sheet20!$C$2:$D$279,2,0) -> WOW
A12: 4 | B12: RAJDEEP KHANDU GAIKWAD | C12: 27343132 | D12: 44 | E12: 1 | F12: 32 | G12: 37 | H12: 92 | I12: 1 | J12: 168 | K12: JS | L12: =VLOOKUP(C12,Sheet20!$C$2:$D$279,2,0) -> WOW
A13: 5 | B13: PIYUSH PAWAR | C13: 25800415 | D13: 40 | E13: 10 | F13: 39 | G13: 9 | H13: 88 | I13: 7 | J13: 167 | K13: JS | L13: =VLOOKUP(C13,Sheet20!$C$2:$D$279,2,0) -> WIZ
A14: 6 | B14: PRATHEMESH BADAVE | C14: 27355088 | D14: 43 | E14: 5 | F14: 42 | G14: 3 | H14: 80 | I14: 20 | J14: 165 | K14: PANDHARPUR | L14: =VLOOKUP(C14,Sheet20!$C$2:$D$279,2,0) -> #N/A
A15: 7 | B15: JAYRAJ HUGAR | C15: 23000008 | D15: 38 | E15: 15 | F15: 35 | G15: 19 | H15: 90 | I15: 3 | J15: 163 | K15: JS | L15: =VLOOKUP(C15,Sheet20!$C$2:$D$279,2,0) -> WOW
A16: 8 | B16: KARTIK KULKARNI | C16: 23000009 | D16: 43 | E16: 5 | F16: 34 | G16: 27 | H16: 86 | I16: 8 | J16: 163 | K16: JS | L16: =VLOOKUP(C16,Sheet20!$C$2:$D$279,2,0) -> WOW
A17: 9 | B17: OJAS HUMNABADKAR | C17: 25800325 | D17: 44 | E17: 1 | F17: 36 | G17: 15 | H17: 82 | I17: 16 | J17: 162 | K17: JS | L17: =VLOOKUP(C17,Sheet20!$C$2:$D$279,2,0) -> WOW
A18: 10 | B18: SATVIKA MORE | C18: 23000017 | D18: 39 | E18: 11 | F18: 39 | G18: 9 | H18: 82 | I18: 16 | J18: 160 | K18: JS | L18: =VLOOKUP(C18,Sheet20!$C$2:$D$279,2,0) -> WOW
A19: 11 | B19: YATHARTH APPASAHEB PATIL | C19: 27344511 | D19: 33 | E19: 34 | F19: 41 | G19: 5 | H19: 86 | I19: 8 | J19: 160 | K19: JS | L19: =VLOOKUP(C19,Sheet20!$C$2:$D$279,2,0) -> WOW
A20: 12 | B20: VEDIKA REVANSIDDHA ANDHALKAR | C20: 27380101 | D20: 32 | E20: 45 | F20: 34 | G20: 27 | H20: 90 | I20: 3 | J20: 156 | K20: JS | L20: =VLOOKUP(C20,Sheet20!$C$2:$D$279,2,0) -> WOW
... A83: 75 | B83: SARTHAK KATEKAR | C83: 27357191 | D83: 27 | E83: 87 | F83: 25 | G83: 113 | H83: 66 | I83: 76 | J83: 118 | K83: PANDHARPUR | L83: =VLOOKUP(C83,Sheet20!$C$2:$D$279,2,0) -> #N/A
A84: 76 | B84: KUNJAL MANIYAR | C84: 27353386 | D84: 28 | E84: 78 | F84: 31 | G84: 44 | H84: 58 | I84: 115 | J84: 117 | L84: =VLOOKUP(C84,Sheet20!$C$2:$D$279,2,0) -> #N/A
A85: 77 | B85: SIDDHANATH ABHAY JOSHI | C85: 27358357 | D85: 26 | E85: 97 | F85: 29 | G85: 65 | H85: 62 | I85: 94 | J85: 117 | K85: HO | L85: =VLOOKUP(C85,Sheet20!$C$2:$D$279,2,0) -> WIZ
A86: 78 | B86: MAHIR DEEPAK PATEL | C86: 27343230 | D86: 27 | E86: 87 | F86: 32 | G86: 37 | H86: 58 | I86: 115 | J86: 117 | K86: HO | L86: =VLOOKUP(C86,Sheet20!$C$2:$D$279,2,0) -> WIZ
A87: 79 | B87: TANVI MILIND DOL | C87: 27361453 | D87: 23 | E87: 132 | F87: 30 | G87: 54 | H87: 64 | I87: 84 | J87: 117 | K87: HO | L87: =VLOOKUP(C87,Sheet20!$C$2:$D$279,2,0) -> WIZ
A88: 80 | B88: SHAMIK SUBHASH GAIKWAD | C88: 27370076 | D88: 30 | E88: 64 | F88: 25 | G88: 113 | H88: 62 | I88: 94 | J88: 117 | K88: JS | L88: =VLOOKUP(C88,Sheet20!$C$2:$D$279,2,0) -> WIZ
A89: 81 | B89: SHRIYASH JADHAV | C89: 27358636 | D89: 28 | E89: 78 | F89: 34 | G89: 27 | H89: 54 | I89: 138 | J89: 116 | K89: PANDHARPUR | L89: =VLOOKUP(C89,Sheet20!$C$2:$D$279,2,0) -> #N/A
A90: 82 | B90: ADITYA SHINDE | C90: 27355555 | D90: 22 | E90: 144 | F90: 22 | G90: 149 | H90: 72 | I90: 42 | J90: 116 | K90: PANDHARPUR | L90: =VLOOKUP(C90,Sheet20!$C$2:$D$279,2,0) -> #N/A
A91: 83 | B91: VAISHNAVI JAYANT HOLEYPATIL | C91: 27354026 | D91: 23 | E91: 132 | F91: 25 | G91: 113 | H91: 68 | I91: 60 | J91: 116 | K91: JS | L91: =VLOOKUP(C91,Sheet20!$C$2:$D$279,2,0) -> WIZ
A92: 84 | B92: SHIVSHARAN SANGALLE | C92: 23000018 | D92: 30 | E92: 64 | F92: 30 | G92: 54 | H92: 56 | I92: 127 | J92: 116 | K92: JS | L92: =VLOOKUP(C92,Sheet20!$C$2:$D$279,2,0) -> WIZ
A93: 85 | B93: VIRAJ SACHIN PATIL | C93: 27340125 | D93: 23 | E93: 132 | F93: 25 | G93: 113 | H93: 68 | I93: 60 | J93: 116 | K93: JS | L93: =VLOOKUP(C93,Sheet20!$C$2:$D$279,2,0) -> WIZ
A94: 86 | B94: VINAYAK ASHWIN PAWAR | C94: 27337465 | D94: 18 | E94: 210 | F94: 22 | G94: 149 | H94: 76 | I94: 30 | J94: 116 | K94: JS | L94: =VLOOKUP(C94,Sheet20!$C$2:$D$279,2,0) -> WIZ
A95: 87 | B95: SHRAVNI VIJAY BHOSALE | C95: 27379233 | D95: 15 | E95: 254 | F95: 30 | G95: 54 | H95: 70 | I95: 51 | J95: 115 | K95: JS | L95: =VLOOKUP(C95,Sheet20!$C$2:$D$279,2,0) -> WIZ
A96: 88 | B96: SHIVANI MAYUR WAGHMODE | C96: 27356628 | D96: 29 | E96: 70 | F96: 27 | G96: 83 | H96: 58 | I96: 115 | J96: 114 | K96: AC | L96: =VLOOKUP(C96,Sheet20!$C$2:$D$279,2,0) -> #N/A
... A343: 335 | B343: SAI RAMDAS MALACHE | C343: 27359484 | D343: 7 | E343: 333 | F343: 8 | G343: 321 | H343: 14 | I343: 334 | J343: 29 | K343: HO | L343: =VLOOKUP(C343,Sheet20!$C$2:$D$279,2,0) -> COC
A344: STUDENTS WHOSE NAMES ARE NOT IN RANK LIST,WERE ABSENT FOR THE TEST

Sheet BTEST711TH JAN 26
A1: BAKLIWAL TUTORIALS
A2: JEE-2027 MAINS BTEST - 07 RESULT 11 JANUARY 2026
A3: TOP 107 STUDENTS IN THE SUBJECT
A4: 108 - 214 STUDENTS IN THE SUBJECT
A5: 215 - 322 STUDENTS IN THE SUBJECT
B6: MEDIAN MARKS | D6: 27 | F6: 36 | H6: 30.5 | J6: 88.5
B7: MAX | D7: 100 | F7: 100 | H7: 100 | J7: 300
A8: TOTAL RANK | B8: STUDENT NAME | C8: ROLL NO. | D8: PHY | E8: PHY RANK | F8: CHEM | G8: CHE RANK | H8: MATHS | I8: MATH RANK | J8: TOTAL | K8: BRANCH | L8: BATCH
A9: 1 | B9: KETKI KULKARNI | C9: 23000010 | D9: 78 | E9: 5 | F9: 88 | G9: 1 | H9: 78 | I9: 2 | J9: 244 | K9: JS | L9: WOW
A10: 2 | B10: ISHAN PHADE | C10: 27353204 | D10: 79 | E10: 2 | F10: 81 | G10: 3 | H10: 69 | I10: 5 | J10: 229 | K10: PANDHARPUR
A11: 3 | B11: KARTIK KULKARNI | C11: 23000009 | D11: 80 | E11: 1 | F11: 76 | G11: 8 | H11: 68 | I11: 8 | J11: 224 | K11: JS | L11: WOW
A12: 4 | B12: OJAS HUMNABADKAR | C12: 25800325 | D12: 60 | E12: 26 | F12: 86 | G12: 2 | H12: 68 | I12: 8 | J12: 214 | K12: JS | L12: WOW
A13: 5 | B13: SHREYASH KORE | C13: 27353597 | D13: 70 | E13: 11 | F13: 54 | G13: 69 | H13: 86 | I13: 1 | J13: 210 | K13: PANDHARPUR
A14: 6 | B14: JAYRAJ HUGAR | C14: 23000008 | D14: 73 | E14: 7 | F14: 76 | G14: 8 | H14: 57 | I14: 27 | J14: 206 | K14: JS | L14: WOW
A15: 7 | B15: TRISHA SHANKAR BHANDARI | C15: 27350345 | D15: 70 | E15: 11 | F15: 75 | G15: 10 | H15: 57 | I15: 27 | J15: 202 | K15: JS | L15: WOW
A16: 8 | B16: SUMIT ANNASAHEB TAKADE | C16: 27371780 | D16: 75 | E16: 6 | F16: 54 | G16: 69 | H16: 71 | I16: 4 | J16: 200 | K16: JS | L16: WOW
A17: 9 | B17: OJAS AKASH REPAL | C17: 26850028 | D17: 66 | E17: 15 | F17: 78 | G17: 5 | H17: 56 | I17: 31 | J17: 200 | K17: JS | L17: WOW
A18: 10 | B18: VEDIKA REVANSIDDHA ANDHALKAR | C18: 27380101 | D18: 64 | E18: 21 | F18: 64 | G18: 30 | H18: 69 | I18: 5 | J18: 197 | K18: JS | L18: WOW
A19: 11 | B19: SATVIKA MORE | C19: 23000017 | D19: 73 | E19: 7 | F19: 75 | G19: 10 | H19: 47 | I19: 65 | J19: 195 | K19: JS | L19: WOW
A20: 12 | B20: PRATHEMESH BADAVE | C20: 27355088 | D20: 67 | E20: 13 | F20: 59 | G20: 40 | H20: 69 | I20: 5 | J20: 195 | K20: PANDHARPUR
A21: 13 | B21: ARNAV THITE | C21: 26850027 | D21: 79 | E21: 2 | F21: 59 | G21: 40 | H21: 56 | I21: 31 | J21: 194 | K21: JS | L21: WOW
A22: 14 | B22: ARYAN SHAMKUMAR DESHMUKH | C22: 27343303 | D22: 66 | E22: 15 | F22: 61 | G22: 35 | H22: 61 | I22: 20 | J22: 188 | K22: JS | L22: WOW
A23: 15 | B23: SHRIJIT BHOSALE | C23: 27384156 | D23: 58 | E23: 29 | F23: 78 | G23: 5 | H23: 51 | I23: 52 | J23: 187 | K23: HO | L23: WIZ
A24: 16 | B24: PRAGUN VINEET RATHI | C24: 27343975 | D24: 67 | E24: 13 | F24: 53 | G24: 75 | H24: 64 | I24: 15 | J24: 184 | K24: JS | L24: WOW
A25: 17 | B25: VAISHNAVI ALAND | C25: 27347172 | D25: 45 | E25: 74 | F25: 71 | G25: 15 | H25: 68 | I25: 8 | J25: 184 | K25: JS | L25: WOW
A26: 18 | B26: SANKET SHIVAPUTRA BUKKANURE | C26: 27333715 | D26: 72 | E26: 9 | F26: 56 | G26: 59 | H26: 56 | I26: 31 | J26: 184 | K26: JS | L26: WOW
A27: 19 | B27: SURYAANSH SHRINIWAS CHIPPA | C27: 27363118 | D27: 57 | E27: 33 | F27: 67 | G27: 24 | H27: 59 | I27: 21 | J27: 183 | K27: HO
A28: 20 | B28: ANIMESH CHAVAN | C28: 23000004 | D28: 71 | E28: 10 | F28: 63 | G28: 31 | H28: 48 | I28: 61 | J28: 182 | K28: JS | L28: WOW
A29: 21 | B29: SHREYA VIJAYKUMAR BIRADAR | C29: 27340955 | D29: 50 | E29: 55 | F29: 78 | G29: 5 | H29: 54 | I29: 40 | J29: 182 | K29: JS | L29: WOW
A30: 22 | B30: SHRUTI SHIVAJI KANHERE | C30: 27370128 | D30: 65 | E30: 19 | F30: 52 | G30: 82 | H30: 64 | I30: 15 | J30: 181 | K30: JS | L30: WIZ
A31: 23 | B31: ARYAN NALAWADE | C31: 27353485 | D31: 48 | E31: 63 | F31: 66 | G31: 26 | H31: 67 | I31: 12 | J31: 181 | K31: PANDHARPUR
A32: 24 | B32: VAISHNAVI VAIBHAV MORE | C32: 27344697 | D32: 51 | E32: 50 | F32: 70 | G32: 17 | H32: 59 | I32: 21 | J32: 180 | K32: JS | L32: WOW
A33: 25 | B33: PIYUSH PAWAR | C33: 25800415 | D33: 42 | E33: 90 | F33: 72 | G33: 14 | H33: 64 | I33: 15 | J33: 178 | K33: JS | L33: WOW
A34: 26 | B34: ANANYA GOVIND ANAGUNDE | C34: 27339321 | D34: 55 | E34: 38 | F34: 67 | G34: 24 | H34: 55 | I34: 37 | J34: 177 | K34: JS | L34: WIZ
A35: 27 | B35: PRATIK VILAS VALLAKATI | C35: 27367699 | D35: 60 | E35: 26 | F35: 60 | G35: 36 | H35: 57 | I35: 27 | J35: 177 | K35: AC
A36: 28 | B36: ADESH SOPAN PARDE | C36: 27380580 | D36: 79 | E36: 2 | F36: 42 | G36: 130 | H36: 55 | I36: 37 | J36: 176 | K36: JS | L36: WOW
A37: 29 | B37: YATHARTH APPASAHEB PATIL | C37: 27344511 | D37: 56 | E37: 36 | F37: 54 | G37: 69 | H37: 65 | I37: 14 | J37: 175 | K37: JS | L37: WOW
A38: 30 | B38: SHREYA CHITNIS | C38: 27352438 | D38: 52 | E38: 46 | F38: 68 | G38: 22 | H38: 53 | I38: 43 | J38: 173 | K38: PANDHARPUR
A39: 31 | B39: SAMRUDDHI RAJENDRAKUMAR KOLEKAR | C39: 27368316 | D39: 44 | E39: 81 | F39: 54 | G39: 69 | H39: 72 | I39: 3 | J39: 170 | K39: JS | L39: WIZ
A40: 32 | B40: SARTHAK KATEKAR | C40: 27357191 | D40: 61 | E40: 25 | F40: 53 | G40: 75 | H40: 54 | I40: 40 | J40: 168 | K40: PANDHARPUR
...

Sheet BRTEST-225TH JAN 26
A1: BAKLIWAL TUTORIALS
A2: JEE - 2027 BRTEST - 02 (CET FORMAT) RESULT 25 JANUARY 2026
A3: TOP 109 STUDENT IN THE SUBJECT
A4: 110 - 218 STUDENT IN THE SUBJECT
A5: 219 - 328 STUDENT IN THE SUBJECT
B6: MEDIAN MARKS | D6: 21 | F6: 24 | H6: 72 | J6: 91
B7: MAX | D7: 50 | F7: 50 | H7: 100 | J7: 200
A8: TOTAL RANK | B8: STUDENT NAME | C8: ROLL NO | D8: PHY | E8: PHY RANK | F8: CHEM | G8: CHE RANK | H8: MATHS | I8: MATH RANK | J8: TOTAL | K8: BRANCH | L8: BATCH
A9: 1 | B9: KARTIK KULKARNI | C9: 23000009 | D9: 50 | E9: 1 | F9: 43 | G9: 8 | H9: 94 | I9: 3 | J9: 187 | K9: JS | L9: =VLOOKUP(C9,Sheet20!$C$2:$D$279,2,0) -> WOW
A10: 2 | B10: KETKI KULKARNI | C10: 23000010 | D10: 48 | E10: 2 | F10: 46 | G10: 1 | H10: 90 | I10: 6 | J10: 184 | K10: JS | L10: =VLOOKUP(C10,Sheet20!$C$2:$D$279,2,0) -> WOW
A11: 3 | B11: JAYRAJ HUGAR | C11: 23000008 | D11: 44 | E11: 7 | F11: 42 | G11: 11 | H11: 96 | I11: 1 | J11: 182 | K11: JS | L11: =VLOOKUP(C11,Sheet20!$C$2:$D$279,2,0) -> WOW
A12: 4 | B12: OJAS HUMNABADKAR | C12: 25800325 | D12: 46 | E12: 4 | F12: 39 | G12: 22 | H12: 96 | I12: 1 | J12: 181 | K12: JS | L12: =VLOOKUP(C12,Sheet20!$C$2:$D$279,2,0) -> WOW
A13: 5 | B13: PRAGUN VINEET RATHI | C13: 27343975 | D13: 46 | E13: 4 | F13: 45 | G13: 2 | H13: 88 | I13: 8 | J13: 179 | K13: JS | L13: =VLOOKUP(C13,Sheet20!$C$2:$D$279,2,0) -> WOW
A14: 6 | B14: SUMIT ANNASAHEB TAKADE | C14: 27371780 | D14: 41 | E14: 15 | F14: 43 | G14: 8 | H14: 90 | I14: 6 | J14: 174 | K14: JS | L14: =VLOOKUP(C14,Sheet20!$C$2:$D$279,2,0) -> WOW
A15: 7 | B15: ISHAN PHADE | C15: 27353204 | D15: 43 | E15: 9 | F15: 43 | G15: 8 | H15: 88 | I15: 8 | J15: 174 | K15: PANDHARPUR | L15: =VLOOKUP(C15,Sheet20!$C$2:$D$279,2,0) -> #N/A
A16: 8 | B16: SURYAANSH SHRINIWAS CHIPPA | C16: 27363118 | D16: 40 | E16: 21 | F16: 45 | G16: 2 | H16: 84 | I16: 16 | J16: 169 | K16: HO | L16: =VLOOKUP(C16,Sheet20!$C$2:$D$279,2,0) -> WIZ
A17: 9 | B17: ANIMESH CHAVAN | C17: 23000004 | D17: 47 | E17: 3 | F17: 41 | G17: 13 | H17: 80 | I17: 22 | J17: 168 | K17: JS | L17: =VLOOKUP(C17,Sheet20!$C$2:$D$279,2,0) -> WOW
A18: 10 | B18: YATHARTH APPASAHEB PATIL | C18: 27344511 | D18: 32 | E18: 75 | F18: 44 | G18: 6 | H18: 92 | I18: 4 | J18: 168 | K18: JS | L18: =VLOOKUP(C18,Sheet20!$C$2:$D$279,2,0) -> WOW
A19: 11 | B19: SHRAVNI ARVIND GIRAM | C19: 27337339 | D19: 40 | E19: 21 | F19: 36 | G19: 43 | H19: 92 | I19: 4 | J19: 168 | K19: JS | L19: =VLOOKUP(C19,Sheet20!$C$2:$D$279,2,0) -> WOW
A20: 12 | B20: AVADHOOT KULKARNI | C20: 27361589 | D20: 40 | E20: 21 | F20: 41 | G20: 13 | H20: 86 | I20: 13 | J20: 167 | K20: JS | L20: =VLOOKUP(C20,Sheet20!$C$2:$D$279,2,0) -> WOW
... A336: 328 | B336: ADITYA BHAUSAHEB DEVKAR | C336: 27363959 | D336: 7 | E336: 325 | F336: 3 | G336: 326 | H336: 20 | I336: 323 | J336: 30 | K336: HO | L336: =VLOOKUP(C336,Sheet20!$C$2:$D$279,2,0) -> COC
A337: STUDENTS WHOSE NAMES ARE NOT IN RANK LIST,WERE ABSENT FOR THE TEST

Sheet BTEST-808TH FEB 26
A1: BAKLIWAL TUTORIALS
A2: JEE-2027 MAINS BTEST - 08 RESULT 08 FEBRUARY 2026
A3: TOP 106 STUDENTS IN THE SUBJECT
A4: 107 - 212 STUDENTS IN THE SUBJECT
A5: 213 - 318 STUDENTS IN THE SUBJECT
B6: MEDIAN MARKS | D6: 36 | F6: 30 | H6: 30.5 | J6: 96
B7: MAX | D7: 100 | F7: 100 | H7: 100 | J7: 300
A8: TOTAL RANK | B8: STUDENT NAME | C8: ROLL NO. | D8: PHY | E8: PHY RANK | F8: CHEM | G8: CHE RANK | H8: MATHS | I8: MATH RANK | J8: TOTAL | K8: BRANCH | L8: BATCH
A9: 1 | B9: KETKI KULKARNI | C9: 23000010 | D9: 92 | E9: 1 | F9: 96 | G9: 1 | H9: 60 | I9: 45 | J9: 248 | K9: JS | L9: WOW
A10: 2 | B10: ARNAV THITE | C10: 26850027 | D10: 78 | E10: 7 | F10: 82 | G10: 5 | H10: 84 | I10: 2 | J10: 244 | K10: JS | L10: WOW
A11: 3 | B11: PRAGUN VINEET RATHI | C11: 27343975 | D11: 63 | E11: 36 | F11: 91 | G11: 2 | H11: 83 | I11: 3 | J11: 237 | K11: JS | L11: WOW
A12: 4 | B12: PIYUSH PAWAR | C12: 25800415 | D12: 73 | E12: 12 | F12: 80 | G12: 6 | H12: 82 | I12: 4 | J12: 235 | K12: JS | L12: WOW
A13: 5 | B13: KARTIK KULKARNI | C13: 23000009 | D13: 76 | E13: 9 | F13: 80 | G13: 6 | H13: 76 | I13: 11 | J13: 232 | K13: JS | L13: WOW
A14: 6 | B14: SUMIT ANNASAHEB TAKADE | C14: 27371780 | D14: 79 | E14: 6 | F14: 73 | G14: 14 | H14: 79 | I14: 6 | J14: 231 | K14: JS | L14: WOW
A15: 7 | B15: OJAS HUMNABADKAR | C15: 25800325 | D15: 81 | E15: 4 | F15: 75 | G15: 10 | H15: 72 | I15: 22 | J15: 228 | K15: JS | L15: WOW
A16: 8 | B16: SURYAANSH SHRINIWAS CHIPPA | C16: 27363118 | D16: 61 | E16: 44 | F16: 90 | G16: 3 | H16: 75 | I16: 13 | J16: 226 | K16: HO | L16: WOW
A17: 9 | B17: SATVIKA MORE | C17: 23000017 | D17: 70 | E17: 17 | F17: 75 | G17: 10 | H17: 79 | I17: 6 | J17: 224 | K17: JS | L17: WOW
A18: 10 | B18: TRISHA SHANKAR BHANDARI | C18: 27350345 | D18: 63 | E18: 36 | F18: 84 | G18: 4 | H18: 71 | I18: 26 | J18: 218 | K18: HO | L18: WOW
A19: 11 | B19: RAJDEEP KHANDU GAIKWAD | C19: 27343132 | D19: 71 | E19: 14 | F19: 73 | G19: 14 | H19: 68 | I19: 29 | J19: 212 | K19: JS | L19: WOW
A20: 12 | B20: ARYAN SHAMKUMAR DESHMUKH | C20: 27343303 | D20: 65 | E20: 30 | F20: 65 | G20: 22 | H20: 75 | I20: 13 | J20: 205 | K20: JS | L20: WOW
